Workbook
Name Rearchitect: tblRearchitect[Re-Architect]
Name Rehost: tblRehost[Rehost]
Name Replace: tblReplace[Replace]
Name Replatform: tblReplatform[Replatform/Refactor]
Name ResolvedNameList: INDIRECT( VLOOKUP( INDEX('App-to-Server List'!$E:$E,ROW()), Lookups!$J$1:$K$7, 2, FALSE ) )
Name SixRs: Lookups!$A$1:$F$1

Sheet Read Me
G2: Version: | H2: 4.13
G3: Last Update | H3: 45919
B5: Purpose
B6: Use this workbook to bulk upload your known Application & Server associations from your existing CMDB - it does not have to be 100% complete for Dr Migrate to provide insights (accuracy is preferred), although the more mappings the better. Dr Migrate will use this information to map and present insights automatically in the Digital Estate Report. Note - you can also use Dr Migrate's Web UI after bulk uploads to edit applications and change server assignments.
B7: If you don't have an existing CMDB, use Auto-Discovery wizard in Dr Migrate to upload a list of known application names. Dr Migrate's Auto-Discovery feature will then determine application to server mappings for unassociated servers for you, where possible.
B9: IMPORTANT
B10: Do not add any additional columns to the Server List tab. This template needs to remain unaltered in order to be ingested by Dr Migrate.
B13: Start
B14: 1. Review the online documentation for how to best fill out this template here
B15: 2. Fill in the Server List tab with as much information as you can.
B16: 3. Upload completed artefact back into Dr Migrate.

Sheet App-to-Server List
A1: See here for detailed guidance on how to best complete this template
A2: Auto-Populated | B2: Provide the following information where known | H2: Information Only
B3: DROP DOWN LIST | C3: FREE FORM TEXT | D3: DROP DOWN LIST | E3: DROP DOWN LIST | F3: DROP DOWN LIST | G3: FREE FORM TEXT
A4: Server | B4: Assessment Scope | C4: Application Name | D4: Environment | E4: Treatment (optional) | F4: Solution (optional) | G4: Other Solution - if applicable (optional) | H4: Power Status | I4: Operating System | J4: Data Center | K4: SQL Detected | L4: VMWare Description
A5: CIC | B5: In Scope | C5: Potential_App_034 | D5: TBA | E5: Rehost | F5: Azure VM (IaaS) | H5: Unknown | I5: Microsoft Windows 10 (64-bit) | J5: Unknown | K5: No | N5: =IF(OR(ISBLANK(E5),AND(NOT(ISBLANK(E5)),ISBLANK(F5))),FALSE,ISNA(INDEX(Lookups!$A$2:'Lookups'!$D$200, MATCH(F5, INDEX(Lookups!$A$2:'Lookups'!$D$200, , MATCH(IF(E5="Replatform","Replatform/Refactor",IF(E5="Rearchitect","Re-Architect",E5)),Lookups!$A$1:'Lookups'!$D$1, 0)), 0), MATCH(IF(E5="Replatform","Replatform/Refactor",IF(E5="Rearchitect","Re-Architect",E5)), Lookups!$A$1:'Lookups'!$D$1, 0))))
A6: INSCCM03 | B6: Out of Scope | C6: SCCM | D6: Prod | H6: Unknown | I6: Microsoft Windows Server 2016 Datacenter | J6: Unknown | K6: No | N6: =IF(OR(ISBLANK(E6),AND(NOT(ISBLANK(E6)),ISBLANK(F6))),FALSE,ISNA(INDEX(Lookups!$A$2:'Lookups'!$D$200, MATCH(F6, INDEX(Lookups!$A$2:'Lookups'!$D$200, , MATCH(IF(E6="Replatform","Replatform/Refactor",IF(E6="Rearchitect","Re-Architect",E6)),Lookups!$A$1:'Lookups'!$D$1, 0)), 0), MATCH(IF(E6="Replatform","Replatform/Refactor",IF(E6="Rearchitect","Re-Architect",E6)), Lookups!$A$1:'Lookups'!$D$1, 0))))
A7: NCtest01 | B7: In Scope | C7: Unassociated Servers | D7: Unknown | E7: Rehost | F7: Azure VM (IaaS) | H7: Unknown | I7: Microsoft Windows Server 2012 Datacenter | J7: Unknown | K7: No | N7: =IF(OR(ISBLANK(E7),AND(NOT(ISBLANK(E7)),ISBLANK(F7))),FALSE,ISNA(INDEX(Lookups!$A$2:'Lookups'!$D$200, MATCH(F7, INDEX(Lookups!$A$2:'Lookups'!$D$200, , MATCH(IF(E7="Replatform","Replatform/Refactor",IF(E7="Rearchitect","Re-Architect",E7)),Lookups!$A$1:'Lookups'!$D$1, 0)), 0), MATCH(IF(E7="Replatform","Replatform/Refactor",IF(E7="Rearchitect","Re-Architect",E7)), Lookups!$A$1:'Lookups'!$D$1, 0))))
A8: Server name 11 | B8: In Scope | C8: Unassociated Servers | D8: Unknown | E8: Rehost | F8: Azure VM (IaaS) | H8: Unknown | I8: Microsoft Windows 2000 Server (32-bit) | J8: Unknown | K8: No | N8: =IF(OR(ISBLANK(E8),AND(NOT(ISBLANK(E8)),ISBLANK(F8))),FALSE,ISNA(INDEX(Lookups!$A$2:'Lookups'!$D$200, MATCH(F8, INDEX(Lookups!$A$2:'Lookups'!$D$200, , MATCH(IF(E8="Replatform","Replatform/Refactor",IF(E8="Rearchitect","Re-Architect",E8)),Lookups!$A$1:'Lookups'!$D$1, 0)), 0), MATCH(IF(E8="Replatform","Replatform/Refactor",IF(E8="Rearchitect","Re-Architect",E8)), Lookups!$A$1:'Lookups'!$D$1, 0))))
A9: VM_0 | B9: In Scope | C9: SCCM | D9: Prod | E9: Replatform/Refactor | F9: Azure App Service | H9: On | I9: Microsoft Windows Server 2016 or later (64-bit) | J9: HQ | K9: No | N9: =IF(OR(ISBLANK(E9),AND(NOT(ISBLANK(E9)),ISBLANK(F9))),FALSE,ISNA(INDEX(Lookups!$A$2:'Lookups'!$D$200, MATCH(F9, INDEX(Lookups!$A$2:'Lookups'!$D$200, , MATCH(IF(E9="Replatform","Replatform/Refactor",IF(E9="Rearchitect","Re-Architect",E9)),Lookups!$A$1:'Lookups'!$D$1, 0)), 0), MATCH(IF(E9="Replatform","Replatform/Refactor",IF(E9="Rearchitect","Re-Architect",E9)), Lookups!$A$1:'Lookups'!$D$1, 0))))
A10: VM_1 | B10: In Scope | C10: Active Directory | D10: Prod | E10: Retain | H10: On | I10: Microsoft Windows Server 2012 (64-bit) | J10: HQ | K10: No | N10: =IF(OR(ISBLANK(E10),AND(NOT(ISBLANK(E10)),ISBLANK(F10))),FALSE,ISNA(INDEX(Lookups!$A$2:'Lookups'!$D$200, MATCH(F10, INDEX(Lookups!$A$2:'Lookups'!$D$200, , MATCH(IF(E10="Replatform","Replatform/Refactor",IF(E10="Rearchitect","Re-Architect",E10)),Lookups!$A$1:'Lookups'!$D$1, 0)), 0), MATCH(IF(E10="Replatform","Replatform/Refactor",IF(E10="Rearchitect","Re-Architect",E10)), Lookups!$A$1:'Lookups'!$D$1, 0))))
A11: VM_1 | B11: In Scope | C11: CA API Gateway | D11: Dev | E11: Retain | H11: On | I11: Microsoft Windows Server 2012 (64-bit) | J11: HQ | K11: No | N11: =IF(OR(ISBLANK(E11),AND(NOT(ISBLANK(E11)),ISBLANK(F11))),FALSE,ISNA(INDEX(Lookups!$A$2:'Lookups'!$D$200, MATCH(F11, INDEX(Lookups!$A$2:'Lookups'!$D$200, , MATCH(IF(E11="Replatform","Replatform/Refactor",IF(E11="Rearchitect","Re-Architect",E11)),Lookups!$A$1:'Lookups'!$D$1, 0)), 0), MATCH(IF(E11="Replatform","Replatform/Refactor",IF(E11="Rearchitect","Re-Architect",E11)), Lookups!$A$1:'Lookups'!$D$1, 0))))
A12: VM_10 | B12: In Scope | C12: SCCM | D12: Prod | E12: Rehost | F12: Azure VM (IaaS) | H12: On | I12: Red Hat Enterprise Linux Server | J12: HQ | K12: No | N12: =IF(OR(ISBLANK(E12),AND(NOT(ISBLANK(E12)),ISBLANK(F12))),FALSE,ISNA(INDEX(Lookups!$A$2:'Lookups'!$D$200, MATCH(F12, INDEX(Lookups!$A$2:'Lookups'!$D$200, , MATCH(IF(E12="Replatform","Replatform/Refactor",IF(E12="Rearchitect","Re-Architect",E12)),Lookups!$A$1:'Lookups'!$D$1, 0)), 0), MATCH(IF(E12="Replatform","Replatform/Refactor",IF(E12="Rearchitect","Re-Architect",E12)), Lookups!$A$1:'Lookups'!$D$1, 0))))
A13: VM_10 | B13: In Scope | C13: Cloudera | D13: Dev | E13: Rehost | F13: Azure VM (IaaS) | H13: On | I13: Red Hat Enterprise Linux Server | J13: HQ | K13: No | N13: =IF(OR(ISBLANK(E13),AND(NOT(ISBLANK(E13)),ISBLANK(F13))),FALSE,ISNA(INDEX(Lookups!$A$2:'Lookups'!$D$200, MATCH(F13, INDEX(Lookups!$A$2:'Lookups'!$D$200, , MATCH(IF(E13="Replatform","Replatform/Refactor",IF(E13="Rearchitect","Re-Architect",E13)),Lookups!$A$1:'Lookups'!$D$1, 0)), 0), MATCH(IF(E13="Replatform","Replatform/Refactor",IF(E13="Rearchitect","Re-Architect",E13)), Lookups!$A$1:'Lookups'!$D$1, 0))))
A14: VM_10 | B14: In Scope | C14: APT | D14: Prod | E14: Rehost | F14: Azure VM (IaaS) | H14: On | I14: Red Hat Enterprise Linux Server | J14: HQ | K14: No | N14: =IF(OR(ISBLANK(E14),AND(NOT(ISBLANK(E14)),ISBLANK(F14))),FALSE,ISNA(INDEX(Lookups!$A$2:'Lookups'!$D$200, MATCH(F14, INDEX(Lookups!$A$2:'Lookups'!$D$200, , MATCH(IF(E14="Replatform","Replatform/Refactor",IF(E14="Rearchitect","Re-Architect",E14)),Lookups!$A$1:'Lookups'!$D$1, 0)), 0), MATCH(IF(E14="Replatform","Replatform/Refactor",IF(E14="Rearchitect","Re-Architect",E14)), Lookups!$A$1:'Lookups'!$D$1, 0))))
A15: VM_100 | B15: In Scope | C15: DSF | D15: Dev | E15: Rehost | F15: Azure VM (IaaS) | H15: On | I15: Red Hat Enterprise Linux Server | J15: HQ | K15: No | N15: =IF(OR(ISBLANK(E15),AND(NOT(ISBLANK(E15)),ISBLANK(F15))),FALSE,ISNA(INDEX(Lookups!$A$2:'Lookups'!$D$200, MATCH(F15, INDEX(Lookups!$A$2:'Lookups'!$D$200, , MATCH(IF(E15="Replatform","Replatform/Refactor",IF(E15="Rearchitect","Re-Architect",E15)),Lookups!$A$1:'Lookups'!$D$1, 0)), 0), MATCH(IF(E15="Replatform","Replatform/Refactor",IF(E15="Rearchitect","Re-Architect",E15)), Lookups!$A$1:'Lookups'!$D$1, 0))))
A16: VM_100 | B16: In Scope | C16: SCCM | D16: Prod | E16: Rehost | F16: Azure VM (IaaS) | H16: On | I16: Red Hat Enterprise Linux Server | J16: HQ | K16: No | N16: =IF(OR(ISBLANK(E16),AND(NOT(ISBLANK(E16)),ISBLANK(F16))),FALSE,ISNA(INDEX(Lookups!$A$2:'Lookups'!$D$200, MATCH(F16, INDEX(Lookups!$A$2:'Lookups'!$D$200, , MATCH(IF(E16="Replatform","Replatform/Refactor",IF(E16="Rearchitect","Re-Architect",E16)),Lookups!$A$1:'Lookups'!$D$1, 0)), 0), MATCH(IF(E16="Replatform","Replatform/Refactor",IF(E16="Rearchitect","Re-Architect",E16)), Lookups!$A$1:'Lookups'!$D$1, 0))))
A17: VM_101 | B17: Out of Scope | C17: eCommerce | D17: UAT | H17: On | I17: Microsoft Windows Server 2016 or later (64-bit) | J17: HQ | K17: No | N17: =IF(OR(ISBLANK(E17),AND(NOT(ISBLANK(E17)),ISBLANK(F17))),FALSE,ISNA(INDEX(Lookups!$A$2:'Lookups'!$D$200, MATCH(F17, INDEX(Lookups!$A$2:'Lookups'!$D$200, , MATCH(IF(E17="Replatform","Replatform/Refactor",IF(E17="Rearchitect","Re-Architect",E17)),Lookups!$A$1:'Lookups'!$D$1, 0)), 0), MATCH(IF(E17="Replatform","Replatform/Refactor",IF(E17="Rearchitect","Re-Architect",E17)), Lookups!$A$1:'Lookups'!$D$1, 0))))
A18: VM_102 | B18: In Scope | C18: Active Batch | D18: Dev | E18: Rehost | F18: Azure VM (IaaS) | H18: On | I18: Red Hat Enterprise Linux Server | J18: HQ | K18: No | N18: =IF(OR(ISBLANK(E18),AND(NOT(ISBLANK(E18)),ISBLANK(F18))),FALSE,ISNA(INDEX(Lookups!$A$2:'Lookups'!$D$200, MATCH(F18, INDEX(Lookups!$A$2:'Lookups'!$D$200, , MATCH(IF(E18="Replatform","Replatform/Refactor",IF(E18="Rearchitect","Re-Architect",E18)),Lookups!$A$1:'Lookups'!$D$1, 0)), 0), MATCH(IF(E18="Replatform","Replatform/Refactor",IF(E18="Rearchitect","Re-Architect",E18)), Lookups!$A$1:'Lookups'!$D$1, 0))))
A19: VM_102 | B19: In Scope | C19: ELK | D19: Dev | E19: Rehost | F19: Azure VM (IaaS) | H19: On | I19: Red Hat Enterprise Linux Server | J19: HQ | K19: No | N19: =IF(OR(ISBLANK(E19),AND(NOT(ISBLANK(E19)),ISBLANK(F19))),FALSE,ISNA(INDEX(Lookups!$A$2:'Lookups'!$D$200, MATCH(F19, INDEX(Lookups!$A$2:'Lookups'!$D$200, , MATCH(IF(E19="Replatform","Replatform/Refactor",IF(E19="Rearchitect","Re-Architect",E19)),Lookups!$A$1:'Lookups'!$D$1, 0)), 0), MATCH(IF(E19="Replatform","Replatform/Refactor",IF(E19="Rearchitect","Re-Architect",E19)), Lookups!$A$1:'Lookups'!$D$1, 0))))
A20: VM_103 | B20: Out of Scope | C20: ELK | D20: Dev | H20: On | I20: Red Hat Enterprise Linux Server | J20: HQ | K20: No | N20: =IF(OR(ISBLANK(E20),AND(NOT(ISBLANK(E20)),ISBLANK(F20))),FALSE,ISNA(INDEX(Lookups!$A$2:'Lookups'!$D$200, MATCH(F20, INDEX(Lookups!$A$2:'Lookups'!$D$200, , MATCH(IF(E20="Replatform","Replatform/Refactor",IF(E20="Rearchitect","Re-Architect",E20)),Lookups!$A$1:'Lookups'!$D$1, 0)), 0), MATCH(IF(E20="Replatform","Replatform/Refactor",IF(E20="Rearchitect","Re-Architect",E20)), Lookups!$A$1:'Lookups'!$D$1, 0))))
A21: VM_104 | B21: In Scope | C21: FFA | D21: Dev | E21: Rehost | F21: Azure VM (IaaS) | H21: On | I21: Red Hat Enterprise Linux Server | J21: HQ | K21: No | N21: =IF(OR(ISBLANK(E21),AND(NOT(ISBLANK(E21)),ISBLANK(F21))),FALSE,ISNA(INDEX(Lookups!$A$2:'Lookups'!$D$200, MATCH(F21, INDEX(Lookups!$A$2:'Lookups'!$D$200, , MATCH(IF(E21="Replatform","Replatform/Refactor",IF(E21="Rearchitect","Re-Architect",E21)),Lookups!$A$1:'Lookups'!$D$1, 0)), 0), MATCH(IF(E21="Replatform","Replatform/Refactor",IF(E21="Rearchitect","Re-Architect",E21)), Lookups!$A$1:'Lookups'!$D$1, 0))))
A22: VM_105 | B22: In Scope | C22: Unassociated Servers | D22: Unknown | E22: Rehost | F22: Azure VM (IaaS) | H22: On | I22: CentOS 7 (64-bit) | J22: HQ | K22: No | N22: =IF(OR(ISBLANK(E22),AND(NOT(ISBLANK(E22)),ISBLANK(F22))),FALSE,ISNA(INDEX(Lookups!$A$2:'Lookups'!$D$200, MATCH(F22, INDEX(Lookups!$A$2:'Lookups'!$D$200, , MATCH(IF(E22="Replatform","Replatform/Refactor",IF(E22="Rearchitect","Re-Architect",E22)),Lookups!$A$1:'Lookups'!$D$1, 0)), 0), MATCH(IF(E22="Replatform","Replatform/Refactor",IF(E22="Rearchitect","Re-Architect",E22)), Lookups!$A$1:'Lookups'!$D$1, 0))))
A23: VM_106 | B23: In Scope | C23: DotNetApp | D23: Dev | E23: Replace | F23: Azure Container Apps | H23: On | I23: Microsoft Windows Server 2016 or later (64-bit) | J23: HQ | K23: No | L23: SIT Web (.Net) | N23: =IF(OR(ISBLANK(E23),AND(NOT(ISBLANK(E23)),ISBLANK(F23))),FALSE,ISNA(INDEX(Lookups!$A$2:'Lookups'!$D$200, MATCH(F23, INDEX(Lookups!$A$2:'Lookups'!$D$200, , MATCH(IF(E23="Replatform","Replatform/Refactor",IF(E23="Rearchitect","Re-Architect",E23)),Lookups!$A$1:'Lookups'!$D$1, 0)), 0), MATCH(IF(E23="Replatform","Replatform/Refactor",IF(E23="Rearchitect","Re-Architect",E23)), Lookups!$A$1:'Lookups'!$D$1, 0))))
A24: VM_107 | B24: In Scope | C24: OLTC | D24: Dev | E24: Rehost | F24: Azure VM (IaaS) | H24: On | I24: Red Hat Enterprise Linux Server | J24: HQ | K24: No | N24: =IF(OR(ISBLANK(E24),AND(NOT(ISBLANK(E24)),ISBLANK(F24))),FALSE,ISNA(INDEX(Lookups!$A$2:'Lookups'!$D$200, MATCH(F24, INDEX(Lookups!$A$2:'Lookups'!$D$200, , MATCH(IF(E24="Replatform","Replatform/Refactor",IF(E24="Rearchitect","Re-Architect",E24)),Lookups!$A$1:'Lookups'!$D$1, 0)), 0), MATCH(IF(E24="Replatform","Replatform/Refactor",IF(E24="Rearchitect","Re-Architect",E24)), Lookups!$A$1:'Lookups'!$D$1, 0))))
A25: VM_107 | B25: In Scope | C25: OLTC | D25: Dev | E25: Rehost | F25: Azure VM (IaaS) | H25: On | I25: Red Hat Enterprise Linux Server | J25: HQ | K25: No | N25: =IF(OR(ISBLANK(E25),AND(NOT(ISBLANK(E25)),ISBLANK(F25))),FALSE,ISNA(INDEX(Lookups!$A$2:'Lookups'!$D$200, MATCH(F25, INDEX(Lookups!$A$2:'Lookups'!$D$200, , MATCH(IF(E25="Replatform","Replatform/Refactor",IF(E25="Rearchitect","Re-Architect",E25)),Lookups!$A$1:'Lookups'!$D$1, 0)), 0), MATCH(IF(E25="Replatform","Replatform/Refactor",IF(E25="Rearchitect","Re-Architect",E25)), Lookups!$A$1:'Lookups'!$D$1, 0))))
A26: VM_108 | B26: In Scope | C26: PaymentHub | D26: Dev | E26: Rehost | F26: Azure VM (IaaS) | H26: On | I26: Red Hat Enterprise Linux Server | J26: HQ | K26: No | N26: =IF(OR(ISBLANK(E26),AND(NOT(ISBLANK(E26)),ISBLANK(F26))),FALSE,ISNA(INDEX(Lookups!$A$2:'Lookups'!$D$200, MATCH(F26, INDEX(Lookups!$A$2:'Lookups'!$D$200, , MATCH(IF(E26="Replatform","Replatform/Refactor",IF(E26="Rearchitect","Re-Architect",E26)),Lookups!$A$1:'Lookups'!$D$1, 0)), 0), MATCH(IF(E26="Replatform","Replatform/Refactor",IF(E26="Rearchitect","Re-Architect",E26)), Lookups!$A$1:'Lookups'!$D$1, 0))))
A27: VM_109 | B27: In Scope | C27: PeopleSoft | D27: Dev | E27: Replace | F27: Azure Container Apps | H27: On | I27: Microsoft Windows Server 2016 or later (64-bit) | J27: HQ | K27: No | N27: =IF(OR(ISBLANK(E27),AND(NOT(ISBLANK(E27)),ISBLANK(F27))),FALSE,ISNA(INDEX(Lookups!$A$2:'Lookups'!$D$200, MATCH(F27, INDEX(Lookups!$A$2:'Lookups'!$D$200, , MATCH(IF(E27="Replatform","Replatform/Refactor",IF(E27="Rearchitect","Re-Architect",E27)),Lookups!$A$1:'Lookups'!$D$1, 0)), 0), MATCH(IF(E27="Replatform","Replatform/Refactor",IF(E27="Rearchitect","Re-Architect",E27)), Lookups!$A$1:'Lookups'!$D$1, 0))))
A28: VM_11 | B28: In Scope | C28: DMS | D28: Dev | E28: Rehost | F28: Azure VM (IaaS) | H28: On | I28: Red Hat Enterprise Linux Server | J28: HQ | K28: No | N28: =IF(OR(ISBLANK(E28),AND(NOT(ISBLANK(E28)),ISBLANK(F28))),FALSE,ISNA(INDEX(Lookups!$A$2:'Lookups'!$D$200, MATCH(F28, INDEX(Lookups!$A$2:'Lookups'!$D$200, , MATCH(IF(E28="Replatform","Replatform/Refactor",IF(E28="Rearchitect","Re-Architect",E28)),Lookups!$A$1:'Lookups'!$D$1, 0)), 0), MATCH(IF(E28="Replatform","Replatform/Refactor",IF(E28="Rearchitect","Re-Architect",E28)), Lookups!$A$1:'Lookups'!$D$1, 0))))
A29: VM_110 | B29: In Scope | C29: Unassociated Servers | D29: Unknown | E29: Rehost | F29: Azure VM (IaaS) | H29: Off | I29: Microsoft Windows Server 2012 (64-bit) | J29: HQ | K29: No | L29: SSIS Job Server and RS CAT. Use 10.22.1.209 SSIS 2012 Job server. To convert SQL edition (SIT Reporting Server) | N29: =IF(OR(ISBLANK(E29),AND(NOT(ISBLANK(E29)),ISBLANK(F29))),FALSE,ISNA(INDEX(Lookups!$A$2:'Lookups'!$D$200, MATCH(F29, INDEX(Lookups!$A$2:'Lookups'!$D$200, , MATCH(IF(E29="Replatform","Replatform/Refactor",IF(E29="Rearchitect","Re-Architect",E29)),Lookups!$A$1:'Lookups'!$D$1, 0)), 0), MATCH(IF(E29="Replatform","Replatform/Refactor",IF(E29="Rearchitect","Re-Architect",E29)), Lookups!$A$1:'Lookups'!$D$1, 0))))
A30: VM_111 | B30: In Scope | C30: Unassociated Servers | D30: Unknown | E30: Rehost | F30: Azure VM (IaaS) | H30: On | I30: CentOS 7 (64-bit) | J30: HQ | K30: No | N30: =IF(OR(ISBLANK(E30),AND(NOT(ISBLANK(E30)),ISBLANK(F30))),FALSE,ISNA(INDEX(Lookups!$A$2:'Lookups'!$D$200, MATCH(F30, INDEX(Lookups!$A$2:'Lookups'!$D$200, , MATCH(IF(E30="Replatform","Replatform/Refactor",IF(E30="Rearchitect","Re-Architect",E30)),Lookups!$A$1:'Lookups'!$D$1, 0)), 0), MATCH(IF(E30="Replatform","Replatform/Refactor",IF(E30="Rearchitect","Re-Architect",E30)), Lookups!$A$1:'Lookups'!$D$1, 0))))
A31: VM_112 | B31: In Scope | C31: Potential_App_015 | D31: TBA | E31: Rehost | F31: Azure VM (IaaS) | H31: On | I31: Other 3.x Linux (64-bit) | J31: HQ | K31: No | L31: Proofpoint Enterprise Protection | N31: =IF(OR(ISBLANK(E31),AND(NOT(ISBLANK(E31)),ISBLANK(F31))),FALSE,ISNA(INDEX(Lookups!$A$2:'Lookups'!$D$200, MATCH(F31, INDEX(Lookups!$A$2:'Lookups'!$D$200, , MATCH(IF(E31="Replatform","Replatform/Refactor",IF(E31="Rearchitect","Re-Architect",E31)),Lookups!$A$1:'Lookups'!$D$1, 0)), 0), MATCH(IF(E31="Replatform","Replatform/Refactor",IF(E31="Rearchitect","Re-Architect",E31)), Lookups!$A$1:'Lookups'!$D$1, 0))))
A32: VM_113 | B32: In Scope | C32: Potential_App_015 | D32: TBA | E32: Rehost | F32: Azure VM (IaaS) | H32: On | I32: Other 3.x Linux (64-bit) | J32: HQ | K32: No | L32: Proofpoint Enterprise Protection | N32: =IF(OR(ISBLANK(E32),AND(NOT(ISBLANK(E32)),ISBLANK(F32))),FALSE,ISNA(INDEX(Lookups!$A$2:'Lookups'!$D$200, MATCH(F32, INDEX(Lookups!$A$2:'Lookups'!$D$200, , MATCH(IF(E32="Replatform","Replatform/Refactor",IF(E32="Rearchitect","Re-Architect",E32)),Lookups!$A$1:'Lookups'!$D$1, 0)), 0), MATCH(IF(E32="Replatform","Replatform/Refactor",IF(E32="Rearchitect","Re-Architect",E32)), Lookups!$A$1:'Lookups'!$D$1, 0))))
A33: VM_114 | B33: In Scope | C33: Potential_App_015 | D33: TBA | E33: Rehost | F33: Azure VM (IaaS) | H33: On | I33: Other 3.x Linux (64-bit) | J33: HQ | K33: No | L33: Proofpoint Enterprise Protection | N33: =IF(OR(ISBLANK(E33),AND(NOT(ISBLANK(E33)),ISBLANK(F33))),FALSE,ISNA(INDEX(Lookups!$A$2:'Lookups'!$D$200, MATCH(F33, INDEX(Lookups!$A$2:'Lookups'!$D$200, , MATCH(IF(E33="Replatform","Replatform/Refactor",IF(E33="Rearchitect","Re-Architect",E33)),Lookups!$A$1:'Lookups'!$D$1, 0)), 0), MATCH(IF(E33="Replatform","Replatform/Refactor",IF(E33="Rearchitect","Re-Architect",E33)), Lookups!$A$1:'Lookups'!$D$1, 0))))
A34: VM_115 | B34: In Scope | C34: Potential_App_015 | D34: TBA | E34: Rehost | F34: Azure VM (IaaS) | H34: On | I34: Other 3.x Linux (64-bit) | J34: HQ | K34: No | L34: Proofpoint Enterprise Protection | N34: =IF(OR(ISBLANK(E34),AND(NOT(ISBLANK(E34)),ISBLANK(F34))),FALSE,ISNA(INDEX(Lookups!$A$2:'Lookups'!$D$200, MATCH(F34, INDEX(Lookups!$A$2:'Lookups'!$D$200, , MATCH(IF(E34="Replatform","Replatform/Refactor",IF(E34="Rearchitect","Re-Architect",E34)),Lookups!$A$1:'Lookups'!$D$1, 0)), 0), MATCH(IF(E34="Replatform","Replatform/Refactor",IF(E34="Rearchitect","Re-Architect",E34)), Lookups!$A$1:'Lookups'!$D$1, 0))))
A35: VM_116 | B35: In Scope | C35: Potential_App_015 | D35: TBA | E35: Rehost | F35: Azure VM (IaaS) | H35: On | I35: Other 3.x Linux (64-bit) | J35: HQ | K35: No | L35: Proofpoint Enterprise Protection | N35: =IF(OR(ISBLANK(E35),AND(NOT(ISBLANK(E35)),ISBLANK(F35))),FALSE,ISNA(INDEX(Lookups!$A$2:'Lookups'!$D$200, MATCH(F35, INDEX(Lookups!$A$2:'Lookups'!$D$200, , MATCH(IF(E35="Replatform","Replatform/Refactor",IF(E35="Rearchitect","Re-Architect",E35)),Lookups!$A$1:'Lookups'!$D$1, 0)), 0), MATCH(IF(E35="Replatform","Replatform/Refactor",IF(E35="Rearchitect","Re-Architect",E35)), Lookups!$A$1:'Lookups'!$D$1, 0))))
A36: VM_117 | B36: In Scope | C36: Potential_App_015 | D36: TBA | E36: Rehost | F36: Azure VM (IaaS) | H36: On | I36: Other 3.x Linux (64-bit) | J36: HQ | K36: No | L36: Proofpoint Enterprise Protection | N36: =IF(OR(ISBLANK(E36),AND(NOT(ISBLANK(E36)),ISBLANK(F36))),FALSE,ISNA(INDEX(Lookups!$A$2:'Lookups'!$D$200, MATCH(F36, INDEX(Lookups!$A$2:'Lookups'!$D$200, , MATCH(IF(E36="Replatform","Replatform/Refactor",IF(E36="Rearchitect","Re-Architect",E36)),Lookups!$A$1:'Lookups'!$D$1, 0)), 0), MATCH(IF(E36="Replatform","Replatform/Refactor",IF(E36="Rearchitect","Re-Architect",E36)), Lookups!$A$1:'Lookups'!$D$1, 0))))
A37: VM_118 | B37: In Scope | C37: Potential_App_015 | D37: TBA | E37: Rehost | F37: Azure VM (IaaS) | H37: On | I37: Other 3.x Linux (64-bit) | J37: HQ | K37: No | L37: Proofpoint Enterprise Protection | N37: =IF(OR(ISBLANK(E37),AND(NOT(ISBLANK(E37)),ISBLANK(F37))),FALSE,ISNA(INDEX(Lookups!$A$2:'Lookups'!$D$200, MATCH(F37, INDEX(Lookups!$A$2:'Lookups'!$D$200, , MATCH(IF(E37="Replatform","Replatform/Refactor",IF(E37="Rearchitect","Re-Architect",E37)),Lookups!$A$1:'Lookups'!$D$1, 0)), 0), MATCH(IF(E37="Replatform","Replatform/Refactor",IF(E37="Rearchitect","Re-Architect",E37)), Lookups!$A$1:'Lookups'!$D$1, 0))))
A38: VM_119 | B38: In Scope | C38: Potential_App_015 | D38: TBA | E38: Rehost | F38: Azure VM (IaaS) | H38: On | I38: Other 3.x Linux (64-bit) | J38: HQ | K38: No | L38: Proofpoint Enterprise Protection | N38: =IF(OR(ISBLANK(E38),AND(NOT(ISBLANK(E38)),ISBLANK(F38))),FALSE,ISNA(INDEX(Lookups!$A$2:'Lookups'!$D$200, MATCH(F38, INDEX(Lookups!$A$2:'Lookups'!$D$200, , MATCH(IF(E38="Replatform","Replatform/Refactor",IF(E38="Rearchitect","Re-Architect",E38)),Lookups!$A$1:'Lookups'!$D$1, 0)), 0), MATCH(IF(E38="Replatform","Replatform/Refactor",IF(E38="Rearchitect","Re-Architect",E38)), Lookups!$A$1:'Lookups'!$D$1, 0))))
A39: VM_12 | B39: In Scope | C39: DMS | D39: Dev | E39: Retire | H39: On | I39: Red Hat Enterprise Linux Server | J39: HQ | K39: No | N39: =IF(OR(ISBLANK(E39),AND(NOT(ISBLANK(E39)),ISBLANK(F39))),FALSE,ISNA(INDEX(Lookups!$A$2:'Lookups'!$D$200, MATCH(F39, INDEX(Lookups!$A$2:'Lookups'!$D$200, , MATCH(IF(E39="Replatform","Replatform/Refactor",IF(E39="Rearchitect","Re-Architect",E39)),Lookups!$A$1:'Lookups'!$D$1, 0)), 0), MATCH(IF(E39="Replatform","Replatform/Refactor",IF(E39="Rearchitect","Re-Architect",E39)), Lookups!$A$1:'Lookups'!$D$1, 0))))
A40: VM_120 | B40: In Scope | C40: SharePoint | D40: Dev | E40: Rehost | F40: Azure VM (IaaS) | H40: On | I40: Microsoft Windows Server 2012 (64-bit) | J40: HQ | K40: No | N40: =IF(OR(ISBLANK(E40),AND(NOT(ISBLANK(E40)),ISBLANK(F40))),FALSE,ISNA(INDEX(Lookups!$A$2:'Lookups'!$D$200, MATCH(F40, INDEX(Lookups!$A$2:'Lookups'!$D$200, , MATCH(IF(E40="Replatform","Replatform/Refactor",IF(E40="Rearchitect","Re-Architect",E40)),Lookups!$A$1:'Lookups'!$D$1, 0)), 0), MATCH(IF(E40="Replatform","Replatform/Refactor",IF(E40="Rearchitect","Re-Architect",E40)), Lookups!$A$1:'Lookups'!$D$1, 0))))
...

Sheet Lookups
A1: Rehost | B1: Replatform/Refactor | C1: Replace | D1: Re-Architect | E1: Retain | F1: Retire | J1: DrMName | K1: ExcelName
A2: Azure VM (IaaS) | B2: Azure Analysis Services | C2: Apache Kafka on HDInsight | D2: Apache Kafka on HDInsight | J2: Rehost | K2: =J2
A3: AVS | B3: Azure API Management | C3: App Services | D3: App Services | J3: Replatform/Refactor | K3: Replatform
A4: Other | B4: Azure App Service | C4: Application Insights | D4: Application Insights | J4: Replace | K4: =J4
B5: Azure Automation | C5: ArcGIS SaaS | D5: ArcGIS SaaS | J5: Re-Architect | K5: Rearchitect
B6: Azure Cache for Redis | C6: Azure Active Directory | D6: Azure Active Directory | J6: Retain | K6: =J6
B7: Azure Cognitive Search | C7: Azure AD Connect | D7: Azure AD Connect | J7: Retire | K7: =J7
B8: Azure Container Instances | C8: Azure Analysis Services | D8: Azure Analysis Services
B9: Azure Container Registry | C9: Azure API Gateway | D9: Azure API Gateway
B10: Azure Cosmos DB | C10: Azure API Management | D10: Azure API Management
B11: Azure Data Factory | C11: Azure App Service | D11: Azure App Service
B12: Azure Database for MySQL | C12: Azure Application Gateway | D12: Azure Application Gateway
B13: Azure Database for PostgreSQL | C13: Azure Application Insights | D13: Azure Application Insights
B14: Azure Databricks | C14: Azure Arc | D14: Azure Arc
B15: Azure DevOps Wiki | C15: Azure Automation | D15: Azure Automation
B16: Azure Event Hubs | C16: Azure Automation DSC | D16: Azure Automation DSC
B17: Azure Files | C17: Azure Backup | D17: Azure Backup
B18: Azure Front Door | C18: Azure Bastion | D18: Azure Bastion
B19: Azure Functions | C19: Azure Batch | D19: Azure Batch
... B43: Other | C43: Azure Devops Boards | D43: Azure Devops Boards
C44: Azure DevOps Repos | D44: Azure DevOps Repos
C45: Azure DevOps Services | D45: Azure DevOps Services
C46: Azure Digital Twins | D46: Azure Digital Twins
C47: Azure Disk Encryption | D47: Azure Disk Encryption
C48: Azure Disk Management | D48: Azure Disk Management
C49: Azure Disk Storage | D49: Azure Disk Storage
C50: Azure DNS | D50: Azure DNS
C51: Azure Event Grid | D51: Azure Event Grid
C52: Azure File Storage | D52: Azure File Storage
C53: Azure File Sync | D53: Azure File Sync
C54: Azure Files | D54: Azure Files
C55: Azure Firewall | D55: Azure Firewall
... C189: Other | D189: Other
